<sdf version='1.7'>
  <model name='kobuki_standalone'>
    <link name='base_footprint'>
      <inertial>
        <pose>0.009866 2.6e-05 0.010277 0 -0 0</pose>
        <mass>2.4213</mass>
        <inertia>
          <ixx>0.0224044</ixx>
          <ixy>-2.89213e-06</ixy>
          <ixz>4.10737e-06</ixz>
          <iyy>0.0226237</iyy>
          <iyz>-1.24762e-06</iyz>
          <izz>0.0394834</izz>
        </inertia>
      </inertial>

      <collision name='base_footprint_fixed_joint_lump__base_collision'>
        <pose>0 0 0.06969 0 -0 0</pose>
        <geometry>
          <cylinder>
            <length>0.10938</length>
            <radius>0.178</radius>
          </cylinder>
        </geometry>
      </collision>

      <collision name='base_footprint_fixed_joint_lump__caster_back_link_collision_1'>
        <pose>-0.135 0 0.0192 -1.5708 0 0</pose>
        <geometry>
          <cylinder>
            <length>0.0176</length>
            <radius>0.017</radius>
          </cylinder>
        </geometry>
        <surface>
          <contact>
            <ode>
              <kp>1e+06</kp>
              <kd>100</kd>
              <max_vel>1</max_vel>
              <min_depth>0.001</min_depth>
            </ode>
          </contact>
          <friction>
            <ode>
              <mu>0</mu>
              <mu2>0</mu2>
            </ode>
          </friction>
        </surface>
      </collision>

      <collision name='base_footprint_fixed_joint_lump__caster_front_link_collision_2'>
        <pose>0.115 0 0.0172 -1.5708 0 0</pose>
        <geometry>
          <cylinder>
            <length>0.0176</length>
            <radius>0.017</radius>
          </cylinder>
        </geometry>
        <surface>
          <contact>
            <ode>
              <kp>1e+06</kp>
              <kd>100</kd>
              <max_vel>1</max_vel>
              <min_depth>0.001</min_depth>
            </ode>
          </contact>
          <friction>
            <ode>
              <mu>0</mu>
              <mu2>0</mu2>
            </ode>
          </friction>
        </surface>
      </collision>

      <visual name='base_footprint_fixed_joint_lump__base_link_visual'>
        <pose>-0.02 0.015 0.06219 0 -0 1.6057</pose>
        <geometry>
          <!--<box><size>1 1 1</size></box>-->
          <mesh>
            <scale>1 1 1</scale>
            <uri>model://turtlebot2_gazebo/meshes/main_body_v2.dae</uri>
          </mesh>
        </geometry>
      </visual>
      
      <sensor name='bumpers' type='contact'>
        <always_on>1</always_on>
        <update_rate>50</update_rate>
        <visualize>1</visualize>
        <contact>
          <collision>base_footprint_fixed_joint_lump__base_collision</collision>
          <topic>__default_topic__</topic>
        </contact>
        <plugin name="gazebo_ros_contact_plugin" filename="libgazebo_ros_contact.so">
          <ros>
            <remapping>~/out:=bump_sensor</remapping>
          </ros>
        </plugin>
        <pose>0 0 0.0102 0 -0 0</pose>
      </sensor>

      <sensor name='cliff_sensor_front' type='ray'>
        <always_on>1</always_on>
        <update_rate>50</update_rate>
        <visualize>1</visualize>
        <ray>
          <scan>
            <horizontal>
              <samples>50</samples>
              <resolution>1</resolution>
              <min_angle>-0.0436</min_angle>
              <max_angle>0.0436</max_angle>
            </horizontal>
          </scan>
          <range>
            <min>0.01</min>
            <max>0.15</max>
            <resolution>1</resolution>
          </range>
        </ray>
        <pose>0.156 0 0.0316 3.14159 1.57079 3.14159</pose>
      </sensor>

      <sensor name='cliff_sensor_left' type='ray'>
        <always_on>1</always_on>
        <update_rate>50</update_rate>
        <visualize>1</visualize>
        <ray>
          <scan>
            <horizontal>
              <samples>50</samples>
              <resolution>1</resolution>
              <min_angle>-0.0436</min_angle>
              <max_angle>0.0436</max_angle>
            </horizontal>
          </scan>
          <range>
            <min>0.01</min>
            <max>0.15</max>
            <resolution>1</resolution>
          </range>
        </ray>
        <pose>0.08734 0.13601 0.0316 3.14159 1.57079 3.14159</pose>
      </sensor>

      <sensor name='cliff_sensor_right' type='ray'>
        <always_on>1</always_on>
        <update_rate>50</update_rate>
        <visualize>1</visualize>
        <ray>
          <scan>
            <horizontal>
              <samples>50</samples>
              <resolution>1</resolution>
              <min_angle>-0.0436</min_angle>
              <max_angle>0.0436</max_angle>
            </horizontal>
          </scan>
          <range>
            <min>0.01</min>
            <max>0.15</max>
            <resolution>1</resolution>
          </range>
        </ray>
        <pose>0.085 -0.13601 0.0316 3.14159 1.57079 3.14159</pose>
      </sensor>
      
      <sensor name='imu' type='imu'>
        <plugin name='gazebo_ros_imu_controller' filename='libgazebo_ros_imu_sensor.so'>
          <ros>
            <argument>~/out:=imu</argument>
          </ros>
          <output_type>sensor_msgs/msg/Imu</output_type>
          <body_name>gyro_link</body_name>
          <frame_name>gyro_link</frame_name>
        </plugin>
        <always_on>1</always_on>
        <update_rate>50</update_rate>
        <visualize>0</visualize>
        <imu>
          <noise>
            <type>gaussian</type>
            <rate>
              <mean>0.0</mean>
              <stddev>1.96e-06</stddev>
              <bias_mean>0.0</bias_mean>
              <bias_stddev>0.0</bias_stddev>
            </rate>
            <accel>
              <mean>0.0</mean>
              <stddev>1.7e-2</stddev>
              <bias_mean>0.1</bias_mean>
              <bias_stddev>0.001</bias_stddev>
            </accel>
          </noise>
        </imu>
        <pose>0.056 0.062 0.0304 0 -0 0</pose>
      </sensor>
    </link>

    <joint name='wheel_left_joint' type='revolute'>
      <pose relative_to='base_footprint'>0 0.115 0.0352 -1.5708 0 0</pose>
      <parent>base_footprint</parent>
      <child>wheel_left_link</child>
      <axis>
        <xyz>0 0 1</xyz>
        <limit>
          <lower>-1e+16</lower>
          <upper>1e+16</upper>
        </limit>
        <dynamics>
          <spring_reference>0</spring_reference>
          <spring_stiffness>0</spring_stiffness>
        </dynamics>
      </axis>
    </joint>

    <joint name="lidar_joint" type="fixed">
      <parent >base_footprint</parent>
      <child>base_scan</child>
      <pose relative_to='base_footprint'>0 0 0.171 0 0 0</pose>
      <axis>
        <xyz>0 0 1</xyz>
      </axis>
    </joint>

    <link name='wheel_left_link'>
      <pose relative_to='wheel_left_joint'>0 0 0 0 -0 0</pose>

      <inertial>
        <pose>0 0 0 0 -0 0</pose>
        <mass>0.01</mass>
        <inertia>
          <ixx>0.001</ixx>
          <ixy>0</ixy>
          <ixz>0</ixz>
          <iyy>0.001</iyy>
          <iyz>0</iyz>
          <izz>0.001</izz>
        </inertia>
      </inertial>

      <collision name='wheel_left_link_collision'>
        <pose>0 0 0 0 -0 0</pose>
        <geometry>
          <cylinder>
            <length>0.0206</length>
            <radius>0.035</radius>
          </cylinder>
        </geometry>
        <surface>
          <contact>
            <ode>
              <kp>1e+06</kp>
              <kd>100</kd>
              <max_vel>1</max_vel>
              <min_depth>0.001</min_depth>
            </ode>
          </contact>
          <friction>
            <ode>
              <mu>1</mu>
              <mu2>1</mu2>
            </ode>
          </friction>
        </surface>
      </collision>

      <visual name='wheel_left_link_visual'>
        <pose>0.005 0 0 1.50707963 -0 1.50707963</pose>
        <geometry>
          <!--<box><size>1 1 1</size></box>-->
          <mesh>
            <scale>1 1 1</scale>
            <uri>model://turtlebot2_gazebo/meshes/wheel_v2.dae</uri>
          </mesh>
        </geometry>
      </visual>
    </link>

    <joint name='wheel_right_joint' type='revolute'>
      <pose relative_to='base_footprint'>0 -0.115 0.0352 -1.5708 0 0</pose>
      <parent>base_footprint</parent>
      <child>wheel_right_link</child>
      <axis>
        <xyz>0 0 1</xyz>
        <limit>
          <lower>-1e+16</lower>
          <upper>1e+16</upper>
        </limit>
        <dynamics>
          <spring_reference>0</spring_reference>
          <spring_stiffness>0</spring_stiffness>
        </dynamics>
      </axis>
    </joint>

    <link name='wheel_right_link'>
      <pose relative_to='wheel_right_joint'>0 0 0 0 -0 0</pose>
      <inertial>
        <pose>0 0 0 0 -0 0</pose>
        <mass>0.01</mass>
        <inertia>
          <ixx>0.001</ixx>
          <ixy>0</ixy>
          <ixz>0</ixz>
          <iyy>0.001</iyy>
          <iyz>0</iyz>
          <izz>0.001</izz>
        </inertia>
      </inertial>
      <collision name='wheel_right_link_collision'>
        <pose>0 0 0 0 -0 0</pose>
        <geometry>
          <cylinder>
            <length>0.0206</length>
            <radius>0.035</radius>
          </cylinder>
        </geometry>
        <surface>
          <contact>
            <ode>
              <kp>1e+06</kp>
              <kd>100</kd>
              <max_vel>1</max_vel>
              <min_depth>0.001</min_depth>
            </ode>
          </contact>
          <friction>
            <ode>
              <mu>1</mu>
              <mu2>1</mu2>
            </ode>
          </friction>
        </surface>
      </collision>
      <visual name='wheel_right_link_visual'>
        <pose>0.0125 0 0 1.50707963 -0 1.50707963</pose>
        <geometry>
          <!--<box><size>1 1 1</size></box>-->
          <mesh>
            <scale>1 1 1</scale>
            <uri>model://turtlebot2_gazebo/meshes/wheel_v2.dae</uri>
          </mesh>
        </geometry>
      </visual>
    </link>

    <link name="base_scan">
      <inertial>
        <pose>-0.020 0 0.161 0 0 0</pose>
        <inertia>
          <ixx>0.001</ixx>
          <ixy>0.000</ixy>
          <ixz>0.000</ixz>
          <iyy>0.001</iyy>
          <iyz>0.000</iyz>
          <izz>0.001</izz>
        </inertia>
        <mass>0.114</mass>
      </inertial>

      <collision name="lidar_sensor_collision">
        <pose>-0.020 0 0.161 0 0 0</pose>
        <geometry>
          <cylinder>
            <radius>0.0508</radius>
            <length>0.055</length>
          </cylinder>
        </geometry>
      </collision>

      <visual name="lidar_sensor_visual">
        <pose>-0.032 0 0.171 0 0 0</pose>
        <geometry>
          <mesh>
            <uri>model://turtlebot2_gazebo/meshes/lds.dae</uri>
            <scale>0.001 0.001 0.001</scale>
          </mesh>
        </geometry>
      </visual>

      <sensor name="hls_lfcd_lds" type="ray">
        <always_on>true</always_on>
        <visualize>true</visualize>
        <pose>-0.032 0 0.171 0 0 0</pose>
        <update_rate>35</update_rate>
        <ray>
          <scan>
            <horizontal>
              <samples>1</samples>
              <resolution>1.000000</resolution>
              <min_angle>0.000000</min_angle>
              <max_angle>0.000000</max_angle>
            </horizontal>
            <!-- <horizontal>
              <samples>360</samples>
              <resolution>1.000000</resolution>
              <min_angle>0.000000</min_angle>
              <max_angle>6.280000</max_angle>
            </horizontal> -->
          </scan>
          <range>
            <!--<min>0.120000</min>-->
            <!--<max>3.5</max>-->
            <!--<resolution>0.015000</resolution>-->
            <min>0.1</min>
            <!--<max>63.45676</max>-->
            <max>31.22838</max>
            <resolution>0.030496</resolution>
          </range>
          <noise>
            <type>gaussian</type>
            <mean>0.0</mean>
            <stddev>0.01</stddev>
          </noise>
        </ray>
        <plugin name="turtlebot2_laserscan" filename="libgazebo_ros_ray_sensor.so">
          <ros>
            <!-- <namespace>/tb2</namespace> -->
            <remapping>~/out:=scan</remapping>
          </ros>
          <output_type>sensor_msgs/LaserScan</output_type>
          <frame_name>base_scan</frame_name>
        </plugin>
      </sensor>
    </link>

    <static>0</static>

    <plugin name='differential_drive_controller' filename='libgazebo_ros_diff_drive.so'>
      <update_rate>10</update_rate>
      <left_joint>wheel_left_joint</left_joint>
      <right_joint>wheel_right_joint</right_joint>
      <wheel_separation>0.230</wheel_separation>
      <wheel_diameter>0.070</wheel_diameter>
      <max_wheel_torque>1.0</max_wheel_torque>
      <max_wheel_acceleration>1.0</max_wheel_acceleration>
      <command_topic>cmd_vel</command_topic>
      <publish_odom>1</publish_odom>
      <publish_odom_tf>1</publish_odom_tf>
      <publish_wheel_tf>1</publish_wheel_tf>
      <odometry_topic>odom</odometry_topic>
      <odometry_frame>odom</odometry_frame>
      <robot_base_frame>base_footprint</robot_base_frame>
    </plugin>
  </model>
</sdf>
